---
title: 17 - 错误处理
tags: try,logging,调用栈,raise,except,finally,BaseException,Exception
renderNumberedHeading: true
grammar_cjkRuby: true
---

Author:  Qiao My
Create_Time: 2020-3-15

[toc]


程序运行过程中，发生错误时，可以事先约定返回一个错误代码，通过错误代码可以知道是否有错，及错误原因。
操作系统提供的调用中，返回错误代码非常常见。

但是，单纯使用错误代码表示是否出错十分不便，因为函数本身返回的正常结果和错误代码混在一起，调用者必须用大量代码来判断是否出错。一旦出错，逐级上报，直到某个函数可以处理该错误。

Python 和所有高级语言一样，内置了`try...except...finally...`的错误处理机制。

Python 的错误也是class，所有的错误类型都继承自`BaseException`，所以在使用`except`时需要注意的是，它不但捕获该类型的错误，还把其子类全部捕获。

# 一、try
当某些代码可能出错时，可以用`try`来运行这段代码。
如果执行出错，则后续代码不会继续执行，直接跳转至错误处理代码，即`except`语句块。
执行完`except`后，如果有`finally`语句块，则执行。

语法：
```python
try : 
    '语句块'
except [expression ["as" identifier]] :
    '语句块'
["except" [expression_0 ["as" identifier_0]] :]...
["else" ":" suite]
["finally" ":" suite]
```

注意：
- except 语句不是必须的，finally 也不是必须的，但二者必须有一个。
- 允许存在多个 except 子句，但必须是连续的。
- except 子句允许**以元组的形式同时指定多个 异常处理器**。
- 无表达式的 except必须是最后一个 except，表示 匹配任何异常。
- 如果没有 except 子句与异常相匹配，则会在周边代码和发起调用栈上继续搜索异常处理器。除非存在一个 finally 子句正好引发了另一个异常。
- 如果对于同一异常存在有嵌套的两个处理器，而异常发生于内层处理器的 try 子句中，则外层处理器将不会处理该异常。
- 与上一条类似，`try...except`支持跨越多层调用，也就是说，不需要每个可能出错的地方去捕获错误，只要在合适的层次去捕获错误就可以了(如main()函数中)。
- 如果try语句中没有错误，`else`子句将被执行。else 语句中的异常不会由之前的 except 子句处理。

# 二、调用栈
如果错误没有被捕获，它就会一直往上抛，最后被Python 解释器捕获，打印一个错误信息，然后程序退出。
出错并不可怕，可怕的是不知道哪里出错了。**解读错误信息是定位错误的关键**， ==出错的时候，一定要分析错误的调用栈信息，才能定位错误的位置 #ff0000==。
。从上到下就是整个错误的调用函数链。

# 三、记录错误(logging 模块)
如果不捕获错误，Python解释器会打印出错误堆栈，但程序也被结束了。
既然能捕获错误，就可以把错误堆栈打印出来，然后分析错误原因，同时，也让程序继续执行下去。

Python 内置的`logging`模块可以非常容易的记录错误信息，并在执行完程序后正常退出。
例：
```python
import logging

def foo(s):
    return 10 / int(s)

def bar(s):
    return foo(s) * 2

def main():
    try:
        bar('0')
    except Exception as e:
        logging.exception(e)
# 调用
main()
print('END')
```

## 1. logging 模块
这个模块为应用与库定义了实现灵活的事件日志系统的函数与类.

记录信息的级别包括：
| 级别 | 数值 |
| --- | --- |
| CRITICAL | 50 |
| ERROR | 40 |
| WARNING | 30 |
| INFO | 20 |
| DEBUG | 10 |
| NOTSET | 0 |

| 常用方法 | 秒数 |
| info(msg, *args, **kwargs) | 记录INFO级别的消息。 |
| basicConfig(**kwargs) | 配置默认日志记录器 root 的相关属性 |

basicConfig支持的关键字如下
| 格式 | 描述 |
| --- | --- |
| filename | Specifies that a FileHandler be created, using the specified filename, rather than a StreamHandler. |
| filemode | If filename is specified, open the file in this mode. Defaults to 'a'. |
| format | Use the specified format string for the handler. |
| datefmt | Use the specified date/time format, as accepted by time.strftime(). |
| style | If format is specified, use this style for the format string. One of '%', '{' or '`$`' for printf-style, str.format() or string.Template respectively. Defaults to '%'. |
| level | Set the root logger level to the specified level. |
| stream | Use the specified stream to initialize the StreamHandler. Note that this argument is incompatible with filename - if both are present, a ValueError is raised. |
| handlers | If specified, this should be an iterable of already created handlers to add to the root logger. Any handlers which don't already have a formatter set will be assigned the default formatter created in this function. Note that this argument is incompatible with filename or stream - if both are present, a ValueError is raised. |
| force | If this keyword argument is specified as true, any existing handlers attached to the root logger are removed and closed, before carrying out the configuration as specified by the other arguments. |

例：
```python
import logging
# exp 1
logging.basicConfig(level=logging.INFO)

s = '0'
n = int(s)
logging.info('n = %d' % n)
print(10 / n)

# exp 2
logging.basicConfig(level=logging.DEBUG, format='%(name)s - %(levelname)s - %(message)s')
logging.debug('This will get logged')
# exp 2 输出
root - DEBUG - This will get logged
```

# 四、抛出错误(raise 语句)
因为错误都是class，捕获一个错误就是捕获该class的一个实例。因此错误并不是凭空产生的，而是有意创建并抛出的。
Python 的内置函数会抛出很多类型的错误，我们自己编写的函数也可以抛出错误。
如果要抛出错误，首先根据需要，可以定义一个错误的 class，选择好继承关系，然后，用`raise`语句抛出一个错误的实例。

只有在必要的时候才定义我们自己的错误类型。如果可以选择Python已有的内置错误类型，尽量使用Python内置的错误类型。
例：
```python
class FooError(ValueError):
    pass

def foo(s):
    n = int(s)
    if n==0:
        raise FooError('invalid value: %s' % s)
    return 10 / n
# 调用
foo('0')
```

当前函数不知道怎么处理错误时，可以选择捕获错误，然后将错误向上抛，让顶层调用者去处理。
这里捕获错误(可用于打印)，是便于后续追踪。
例：
```python
def foo(s):
    n = int(s)
    if n==0:
        raise ValueError('invalid value: %s' % s)
    return 10 / n

def bar():
    try:
        foo('0')
    except ValueError as e:
        print('ValueError!')
        raise
# 调用
bar()
```

## 1. raise 语句
语法如下：
```python
raise [expression [from expression]]
```
`raise`语句如果不带参数，就会把当前错误原样抛出。如果当前作用域内没有异常，将引发`RuntimeError`。
`from`子句用于异常串联：如果有该子句，则第二个参数必须为另一个异常或实例，它将作为可写的`__cause__`属性被关联到所引发的异常。
例：
```python
try:
    print(1 / 0)
except Exception as exc:
    raise RuntimeError("Something bad happened") from exc
# 输出
Traceback (most recent call last):
  File "<stdin>", line 2, in <module>
ZeroDivisionError: division by zero

The above exception was the direct cause of the following exception:

Traceback (most recent call last):
  File "<stdin>", line 4, in <module>
RuntimeError: Something bad happened
```


建议：捕获并抛出异常时不要在`raise`后面加上异常对象。因为在Python2 中`trac`信息会从此处截断。Python3中遵从此建议。


# 五、使用内置的语法范式 代替 try 语句
当存在内置的语法范式可以简化异常处理时，应尽量避免使用 try语句思维处理异常。
例：
```python
# should not
try:
    f = open(a_file)
    do_something(f)
finally:
    f.close()

# should 
with open(a_file) as f:
    do_something(f)
```
例：
```python
# should not
try:
    test = Test()
    name = test.name  # not sure if we can get its name
except AttributeError:
    name = 'default'
# should 
name = getattr(test, 'name', 'default')
```


# 六、异常层次结构
内置异常的类层级结构如下：
```python
BaseException
 +-- SystemExit
 +-- KeyboardInterrupt
 +-- GeneratorExit
 +-- Exception
      +-- StopIteration
      +-- StopAsyncIteration
      +-- ArithmeticError
      |    +-- FloatingPointError
      |    +-- OverflowError
      |    +-- ZeroDivisionError
      +-- AssertionError
      +-- AttributeError
      +-- BufferError
      +-- EOFError
      +-- ImportError
      |    +-- ModuleNotFoundError
      +-- LookupError
      |    +-- IndexError
      |    +-- KeyError
      +-- MemoryError
      +-- NameError
      |    +-- UnboundLocalError
      +-- OSError
      |    +-- BlockingIOError
      |    +-- ChildProcessError
      |    +-- ConnectionError
      |    |    +-- BrokenPipeError
      |    |    +-- ConnectionAbortedError
      |    |    +-- ConnectionRefusedError
      |    |    +-- ConnectionResetError
      |    +-- FileExistsError
      |    +-- FileNotFoundError
      |    +-- InterruptedError
      |    +-- IsADirectoryError
      |    +-- NotADirectoryError
      |    +-- PermissionError
      |    +-- ProcessLookupError
      |    +-- TimeoutError
      +-- ReferenceError
      +-- RuntimeError
      |    +-- NotImplementedError
      |    +-- RecursionError
      +-- SyntaxError
      |    +-- IndentationError
      |         +-- TabError
      +-- SystemError
      +-- TypeError
      +-- ValueError
      |    +-- UnicodeError
      |         +-- UnicodeDecodeError
      |         +-- UnicodeEncodeError
      |         +-- UnicodeTranslateError
      +-- Warning
           +-- DeprecationWarning
           +-- PendingDeprecationWarning
           +-- RuntimeWarning
           +-- SyntaxWarning
           +-- UserWarning
           +-- FutureWarning
           +-- ImportWarning
           +-- UnicodeWarning
           +-- BytesWarning
           +-- ResourceWarning
```






# 参考
【错误和异常】https://docs.python.org/zh-cn/3/tutorial/errors.html
【复合语句 - try 语句】https://docs.python.org/zh-cn/3/reference/compound_stmts.html#finally
【异常层次结构】https://docs.python.org/zh-cn/3/library/exceptions.html#exception-hierarchy
【raise 语句】https://docs.python.org/zh-cn/3/reference/simple_stmts.html#raise
【总结：Python中的异常处理】https://segmentfault.com/a/1190000007736783
【Python3 错误和异常】https://www.runoob.com/python3/python3-errors-execptions.html








